Workbook

Sheet Prepaid Summary
A1: Aurisic Prepaid Summary
A2: Reporting period through 4/30/2025
A4: Snapshot pulled from the detailed supporting tabs.
A6: Account | B6: Account # | C6: YTD Prepaids Booked | D6: YTD Amortization | E6: Ending Balance 4/30/2025 | F6: GL Balance 4/30/2025 | G6: Difference
A7: Prepaid Expenses | B7: 1250 | C7: ='Prepaid Expenses'!C56 -> 1087156.2 | D7: ='Prepaid Expenses'!D56 -> 527778.6 | E7: ='Prepaid Expenses'!E56 -> 559377.61 | F7: 559377.61 | G7: =ROUND(E7-F7,2) -> 0
A8: Prepaid Insurance | B8: 1251 | C8: ='Prepaid Insurance'!C41 -> 568698.22 | D8: ='Prepaid Insurance'!D41 -> 198721.52 | E8: ='Prepaid Insurance'!E41 -> 369976.69 | F8: 369976.7 | G8: =ROUND(E8-F8,2) -> -0.01
A9: Total | C9: =SUM(C7:C8) -> 1655854.4 | D9: =SUM(D7:D8) -> 726500.12 | E9: =SUM(E7:E8) -> 929354.3 | F9: =SUM(F7:F8) -> 929354.31 | G9: =SUM(G7:G8) -> -0.01
A12: Monthly Ending Balance Reconciliation
A13: Month | B13: 1250 Schedule | C13: 1250 GL | D13: 1250 Diff | E13: 1251 Schedule | F13: 1251 GL | G13: 1251 Diff
A14: Jan-25 | B14: ='Prepaid Expenses'!E52 -> 518934.86 | C14: 518934.86 | D14: =ROUND(B14-C14,2) -> 0 | E14: ='Prepaid Insurance'!E37 -> 506657.98 | F14: 506657.98 | G14: =ROUND(E14-F14,2) -> 0
A15: Feb-25 | B15: ='Prepaid Expenses'!E53 -> 426673.13 | C15: 426673.13 | D15: =ROUND(B15-C15,2) -> 0 | E15: ='Prepaid Insurance'!E38 -> 461097.55 | F15: 461097.55 | G15: =ROUND(E15-F15,2) -> 0
A16: Mar-25 | B16: ='Prepaid Expenses'!E54 -> 473655.55 | C16: 473655.55 | D16: =ROUND(B16-C16,2) -> 0 | E16: ='Prepaid Insurance'!E39 -> 415537.12 | F16: 415537.13 | G16: =ROUND(E16-F16,2) -> -0.01
A17: Apr-25 | B17: ='Prepaid Expenses'!E55 -> 559377.61 | C17: 559377.61 | D17: =ROUND(B17-C17,2) -> 0 | E17: ='Prepaid Insurance'!E40 -> 369976.69 | F17: 369976.7 | G17: =ROUND(E17-F17,2) -> -0.01

Sheet Prepaid Expenses
A1: Prepaid Expenses (Account #1250)
A2: Aurisic | Reporting period through 4/30/2025
A3: Default assumption applied to all prepaid service invoices: amortize over 6 months starting in the invoice month when no specific period is stated.
A5: Vendor | B5: Invoice # | C5: Invoice Date | D5: Description | E5: Account # | F5: Original Amount | G5: Amortization Start | H5: Amortization End | I5: Months | J5: Monthly Expense | K5: Jan Expense | L5: Jan End Bal | M5: Feb Expense | N5: Feb End Bal | O5: Mar Expense | P5: Mar End Bal | Q5: Apr Expense | R5: Apr End Bal | S5: Ending Balance 4/30/2025
A6: ADOBE MAGENTO | B6: 450522 | C6: 45658 | D6: IT Services | E6: 1250 | F6: 10377.75 | G6: 45658 | H6: 45809 | I6: 6 | J6: 1729.625 | K6: 1729.625 | L6: 8648.125 | M6: 1729.625 | N6: 6918.5 | O6: 1729.625 | P6: 5188.875 | Q6: 1729.625 | R6: 3459.25 | S6: 3459.25
A7: ADOBE MAGENTO | B7: 497516 | C7: 45658 | D7: IT Services | E7: 1250 | F7: 402 | G7: 45658 | H7: 45809 | I7: 6 | J7: 67 | K7: 67 | L7: 335 | M7: 67 | N7: 268 | O7: 67 | P7: 201 | Q7: 67 | R7: 134 | S7: 134
A8: ALTAIR | B8: 684836 | C8: 45658 | D8: IT Services | E8: 1250 | F8: 17302.38 | G8: 45658 | H8: 45809 | I8: 6 | J8: 2883.73 | K8: 2883.73 | L8: 14418.65 | M8: 2883.73 | N8: 11534.92 | O8: 2883.73 | P8: 8651.19 | Q8: 2883.73 | R8: 5767.46 | S8: 5767.46
A9: AMESITE | B9: 322437 | C9: 45658 | D9: IT Services | E9: 1250 | F9: 11250 | G9: 45658 | H9: 45809 | I9: 6 | J9: 1875 | K9: 1875 | L9: 9375 | M9: 1875 | N9: 7500 | O9: 1875 | P9: 5625 | Q9: 1875 | R9: 3750 | S9: 3750
A10: CDW | B10: 327658 | C10: 45658 | D10: IT Services | E10: 1250 | F10: 46629.17 | G10: 45658 | H10: 45809 | I10: 6 | J10: 7771.5283 | K10: 7771.5283 | L10: 38857.642 | M10: 7771.5283 | N10: 31086.113 | O10: 7771.5283 | P10: 23314.585 | Q10: 7771.5283 | R10: 15543.057 | S10: 15543.057
A11: CDW | B11: 408381 | C11: 45658 | D11: IT Services | E11: 1250 | F11: 31146.78 | G11: 45658 | H11: 45809 | I11: 6 | J11: 5191.13 | K11: 5191.13 | L11: 25955.65 | M11: 5191.13 | N11: 20764.52 | O11: 5191.13 | P11: 15573.39 | Q11: 5191.13 | R11: 10382.26 | S11: 10382.26
A12: CDW | B12: 502016 | C12: 45658 | D12: IT Services | E12: 1250 | F12: 11969.99 | G12: 45658 | H12: 45809 | I12: 6 | J12: 1994.9983 | K12: 1994.9983 | L12: 9974.9917 | M12: 1994.9983 | N12: 7979.9933 | O12: 1994.9983 | P12: 5984.995 | Q12: 1994.9983 | R12: 3989.9967 | S12: 3989.9967
A13: CDW | B13: 504643 | C13: 45658 | D13: IT Services | E13: 1250 | F13: 1156.73 | G13: 45658 | H13: 45809 | I13: 6 | J13: 192.78833 | K13: 192.78833 | L13: 963.94167 | M13: 192.78833 | N13: 771.15333 | O13: 192.78833 | P13: 578.365 | Q13: 192.78833 | R13: 385.57667 | S13: 385.57667
A14: CDW | B14: 895791 | C14: 45658 | D14: IT Services | E14: 1250 | F14: 6486.77 | G14: 45658 | H14: 45809 | I14: 6 | J14: 1081.1283 | K14: 1081.1283 | L14: 5405.6417 | M14: 1081.1283 | N14: 4324.5133 | O14: 1081.1283 | P14: 3243.385 | Q14: 1081.1283 | R14: 2162.2567 | S14: 2162.2567
A15: CDW | B15: 235739 | C15: 45689 | D15: IT Services | E15: 1250 | F15: 3968.47 | G15: 45689 | H15: 45839 | I15: 6 | J15: 661.41167 | K15: 0 | M15: 661.41167 | N15: 3307.0583 | O15: 661.41167 | P15: 2645.6467 | Q15: 661.41167 | R15: 1984.235 | S15: 1984.235
A16: CDW | B16: 522712 | C16: 45717 | D16: IT Services | E16: 1250 | F16: 54323.43 | G16: 45717 | H16: 45870 | I16: 6 | J16: 9053.905 | K16: 0 | M16: 0 | O16: 9053.905 | P16: 45269.525 | Q16: 9053.905 | R16: 36215.62 | S16: 36215.62
A17: CDW | B17: 593096 | C17: 45717 | D17: IT Services | E17: 1250 | F17: 31092.5 | G17: 45717 | H17: 45870 | I17: 6 | J17: 5182.0833 | K17: 0 | M17: 0 | O17: 5182.0833 | P17: 25910.417 | Q17: 5182.0833 | R17: 20728.333 | S17: 20728.333
A18: CIMSOURCE | B18: 441154 | C18: 45658 | D18: IT Services | E18: 1250 | F18: 4900 | G18: 45658 | H18: 45809 | I18: 6 | J18: 816.66667 | K18: 816.66667 | L18: 4083.3333 | M18: 816.66667 | N18: 3266.6667 | O18: 816.66667 | P18: 2450 | Q18: 816.66667 | R18: 1633.3333 | S18: 1633.3333
A19: CISCO | B19: 190461 | C19: 45658 | D19: Subscription | E19: 1250 | F19: 28158 | G19: 45658 | H19: 45809 | I19: 6 | J19: 4693 | K19: 4693 | L19: 23465 | M19: 4693 | N19: 18772 | O19: 4693 | P19: 14079 | Q19: 4693 | R19: 9386 | S19: 9386
A20: Connection Business | B20: 255348 | C20: 45717 | D20: Subscription | E20: 1250 | F20: 53798.4 | G20: 45717 | H20: 45870 | I20: 6 | J20: 8966.4 | K20: 0 | M20: 0 | O20: 8966.4 | P20: 44832 | Q20: 8966.4 | R20: 35865.6 | S20: 35865.6
A21: Ex Quanta Inc | B21: 230903 | C21: 45717 | D21: Subscription | E21: 1250 | F21: 9225 | G21: 45717 | H21: 45870 | I21: 6 | J21: 1537.5 | K21: 0 | M21: 0 | O21: 1537.5 | P21: 7687.5 | Q21: 1537.5 | R21: 6150 | S21: 6150
A22: Ex Quanta Inc | B22: 567118 | C22: 45717 | D22: Subscription | E22: 1250 | F22: 9225 | G22: 45717 | H22: 45870 | I22: 6 | J22: 1537.5 | K22: 0 | M22: 0 | O22: 1537.5 | P22: 7687.5 | Q22: 1537.5 | R22: 6150 | S22: 6150
A23: Ex Quanta Inc | B23: 793147 | C23: 45717 | D23: Subscription | E23: 1250 | F23: 9225 | G23: 45717 | H23: 45870 | I23: 6 | J23: 1537.5 | K23: 0 | M23: 0 | O23: 1537.5 | P23: 7687.5 | Q23: 1537.5 | R23: 6150 | S23: 6150
A24: Expertek | B24: 105121 | C24: 45689 | D24: Subscription | E24: 1250 | F24: 9861.82 | G24: 45689 | H24: 45839 | I24: 6 | J24: 1643.6367 | K24: 0 | M24: 1643.6367 | N24: 8218.1833 | O24: 1643.6367 | P24: 6574.5467 | Q24: 1643.6367 | R24: 4930.91 | S24: 4930.91
A25: Global Services | B25: 148472 | C25: 45748 | D25: Technical Services Fee | E25: 1250 | F25: 81000 | G25: 45748 | H25: 45901 | I25: 6 | J25: 13500 | K25: 0 | M25: 0 | O25: 0 | Q25: 13500 | R25: 67500 | S25: 67500
A26: High Radius | B26: 156037 | C26: 45748 | D26: Subscription | E26: 1250 | F26: 31792 | G26: 45748 | H26: 45901 | I26: 6 | J26: 5298.6667 | K26: 0 | M26: 0 | O26: 0 | Q26: 5298.6667 | R26: 26493.333 | S26: 26493.333
A27: High Radius | B27: 262817 | C27: 45748 | D27: Subscription | E27: 1250 | F27: 10000 | G27: 45748 | H27: 45901 | I27: 6 | J27: 1666.6667 | K27: 0 | M27: 0 | O27: 0 | Q27: 1666.6667 | R27: 8333.3333 | S27: 8333.3333
A28: Infopercept | B28: 747801 | C28: 45658 | D28: IT Services | E28: 1250 | F28: 2833.33 | G28: 45658 | H28: 45809 | I28: 6 | J28: 472.22167 | K28: 472.22167 | L28: 2361.1083 | M28: 472.22167 | N28: 1888.8867 | O28: 472.22167 | P28: 1416.665 | Q28: 472.22167 | R28: 944.44333 | S28: 944.44333
A29: INFOR | B29: 179361 | C29: 45658 | D29: Subscription | E29: 1250 | F29: 275000 | G29: 45658 | H29: 45809 | I29: 6 | J29: 45833.333 | K29: 45833.333 | L29: 229166.67 | M29: 45833.333 | N29: 183333.33 | O29: 45833.333 | P29: 137500 | Q29: 45833.333 | R29: 91666.667 | S29: 91666.667
A30: INFOR | B30: 938443 | C30: 45658 | D30: Subscription | E30: 1250 | F30: 29404.1 | G30: 45658 | H30: 45809 | I30: 6 | J30: 4900.6833 | K30: 4900.6833 | L30: 24503.417 | M30: 4900.6833 | N30: 19602.733 | O30: 4900.6833 | P30: 14702.05 | Q30: 4900.6833 | R30: 9801.3667 | S30: 9801.3667
A31: Magento | B31: 829475 | C31: 45748 | D31: IT Services | E31: 1250 | F31: 19601.98 | G31: 45748 | H31: 45901 | I31: 6 | J31: 3266.9967 | K31: 0 | M31: 0 | O31: 0 | Q31: 3266.9967 | R31: 16334.983 | S31: 16334.983
A32: Punchout2Go | B32: 844922 | C32: 45717 | D32: IT Services | E32: 1250 | F32: 16800 | G32: 45717 | H32: 45870 | I32: 6 | J32: 2800 | K32: 0 | M32: 0 | O32: 2800 | P32: 14000 | Q32: 2800 | R32: 11200 | S32: 11200
A33: SENTINEL | B33: 863790 | C33: 45658 | D33: IT Services | E33: 1250 | F33: 26276 | G33: 45658 | H33: 45809 | I33: 6 | J33: 4379.3333 | K33: 4379.3333 | L33: 21896.667 | M33: 4379.3333 | N33: 17517.333 | O33: 4379.3333 | P33: 13138 | Q33: 4379.3333 | R33: 8758.6667 | S33: 8758.6667
A34: Synergetic Data Systems | B34: 908787 | C34: 45658 | D34: IT Services | E34: 1250 | F34: 2725.53 | G34: 45658 | H34: 45809 | I34: 6 | J34: 454.255 | K34: 454.255 | L34: 2271.275 | M34: 454.255 | N34: 1817.02 | O34: 454.255 | P34: 1362.765 | Q34: 454.255 | R34: 908.51 | S34: 908.51
A35: TheUserGroup.org | B35: 692889 | C35: 45658 | D35: IT Services | E35: 1250 | F35: 859 | G35: 45658 | H35: 45809 | I35: 6 | J35: 143.16667 | K35: 143.16667 | L35: 715.83333 | M35: 143.16667 | N35: 572.66667 | O35: 143.16667 | P35: 429.5 | Q35: 143.16667 | R35: 286.33333 | S35: 286.33333
A36: Trac Trenching | B36: 583302 | C36: 45658 | D36: IT Services | E36: 1250 | F36: 5000 | G36: 45658 | H36: 45809 | I36: 6 | J36: 833.33333 | K36: 833.33333 | L36: 4166.6667 | M36: 833.33333 | N36: 3333.3333 | O36: 833.33333 | P36: 2500 | Q36: 833.33333 | R36: 1666.6667 | S36: 1666.6667
A37: TradeCentric LLC | B37: 395398 | C37: 45658 | D37: Building Maintenance | E37: 1250 | F37: 451.73 | G37: 45658 | H37: 45809 | I37: 6 | J37: 75.288333 | K37: 75.288333 | L37: 376.44167 | M37: 75.288333 | N37: 301.15333 | O37: 75.288333 | P37: 225.865 | Q37: 75.288333 | R37: 150.57667 | S37: 150.57667
A38: TradeCentric LLC | B38: 395427 | C38: 45658 | D38: Building Maintenance | E38: 1250 | F38: 1537.5 | G38: 45658 | H38: 45809 | I38: 6 | J38: 256.25 | K38: 256.25 | L38: 1281.25 | M38: 256.25 | N38: 1025 | O38: 256.25 | P38: 768.75 | Q38: 256.25 | R38: 512.5 | S38: 512.5
A39: TradeCentric LLC | B39: 696058 | C39: 45658 | D39: Building Maintenance | E39: 1250 | F39: 3351.25 | G39: 45658 | H39: 45809 | I39: 6 | J39: 558.54167 | K39: 558.54167 | L39: 2792.7083 | M39: 558.54167 | N39: 2234.1667 | O39: 558.54167 | P39: 1675.625 | Q39: 558.54167 | R39: 1117.0833 | S39: 1117.0833
A40: UHY | B40: 342831 | C40: 45748 | D40: Advising | E40: 1250 | F40: 56000 | G40: 45748 | H40: 45901 | I40: 6 | J40: 9333.3333 | K40: 0 | M40: 0 | O40: 0 | Q40: 9333.3333 | R40: 46666.667 | S40: 46666.667
A41: UHY | B41: 798191 | C41: 45748 | D41: Advising | E41: 1250 | F41: 28000 | G41: 45748 | H41: 45901 | I41: 6 | J41: 4666.6667 | K41: 0 | M41: 0 | O41: 0 | Q41: 4666.6667 | R41: 23333.333 | S41: 23333.333
...

Sheet Prepaid Insurance
A1: Prepaid Insurance (Account #1251)
A2: Aurisic | Reporting period through 4/30/2025
A3: Policy assumptions: Good Insurance invoices amortized straight-line over 12 months from 1/1/2025 to 12/31/2025.
A4: BCBS invoices are treated as one month paid in advance: Jan invoice covers Feb, Feb covers Mar, Mar covers Apr, Apr covers May.
A6: Vendor | B6: Invoice # | C6: Invoice Date | D6: Description | E6: Account # | F6: Original Amount | G6: Amortization Start | H6: Amortization End | I6: Months | J6: Monthly Expense | K6: Jan Expense | L6: Jan End Bal | M6: Feb Expense | N6: Feb End Bal | O6: Mar Expense | P6: Mar End Bal | Q6: Apr Expense | R6: Apr End Bal | S6: Ending Balance 4/30/2025
A7: BCBS | B7: 8767 | C7: 45658 | D7: Healthcare | E7: 1251 | F7: 5493.27 | G7: 45689 | H7: 45689 | I7: 1 | J7: 5493.27 | K7: 0 | L7: 5493.27 | M7: 5493.27 | N7: 0 | O7: 0 | P7: 0 | Q7: 0 | R7: 0 | S7: 0
A8: BCBS | B8: 4373 | C8: 45689 | D8: Healthcare | E8: 1251 | F8: 5493.27 | G8: 45717 | H8: 45717 | I8: 1 | J8: 5493.27 | K8: 0 | M8: 0 | N8: 5493.27 | O8: 5493.27 | P8: 0 | Q8: 0 | R8: 0 | S8: 0
A9: BCBS | B9: 6072 | C9: 45717 | D9: Healthcare | E9: 1251 | F9: 5493.27 | G9: 45748 | H9: 45748 | I9: 1 | J9: 5493.27 | K9: 0 | M9: 0 | O9: 0 | P9: 5493.27 | Q9: 5493.27 | R9: 0 | S9: 0
A10: BCBS | B10: 5731 | C10: 45748 | D10: Healthcare | E10: 1251 | F10: 5493.27 | G10: 45778 | H10: 45778 | I10: 1 | J10: 5493.27 | K10: 0 | M10: 0 | O10: 0 | Q10: 0 | R10: 5493.27 | S10: 5493.27
A11: Good Insurance | B11: 1100 | C11: 45658 | D11: Insurance Policy | E11: 1251 | F11: 88270.75 | G11: 45658 | H11: 45992 | I11: 12 | J11: 7355.8958 | K11: 7355.8958 | L11: 80914.854 | M11: 7355.8958 | N11: 73558.958 | O11: 7355.8958 | P11: 66203.062 | Q11: 7355.8958 | R11: 58847.167 | S11: 58847.167
A12: Good Insurance | B12: 1101 | C12: 45658 | D12: Insurance Policy | E12: 1251 | F12: 39128 | G12: 45658 | H12: 45992 | I12: 12 | J12: 3260.6667 | K12: 3260.6667 | L12: 35867.333 | M12: 3260.6667 | N12: 32606.667 | O12: 3260.6667 | P12: 29346 | Q12: 3260.6667 | R12: 26085.333 | S12: 26085.333
A13: Good Insurance | B13: 1102 | C13: 45658 | D13: Insurance Policy | E13: 1251 | F13: 73254.95 | G13: 45658 | H13: 45992 | I13: 12 | J13: 6104.5792 | K13: 6104.5792 | L13: 67150.371 | M13: 6104.5792 | N13: 61045.792 | O13: 6104.5792 | P13: 54941.212 | Q13: 6104.5792 | R13: 48836.633 | S13: 48836.633
A14: Good Insurance | B14: 1103 | C14: 45658 | D14: Insurance Policy | E14: 1251 | F14: 23800 | G14: 45658 | H14: 45992 | I14: 12 | J14: 1983.3333 | K14: 1983.3333 | L14: 21816.667 | M14: 1983.3333 | N14: 19833.333 | O14: 1983.3333 | P14: 17850 | Q14: 1983.3333 | R14: 15866.667 | S14: 15866.667
A15: Good Insurance | B15: 1104 | C15: 45658 | D15: Insurance Policy | E15: 1251 | F15: 11864.44 | G15: 45658 | H15: 45992 | I15: 12 | J15: 988.70333 | K15: 988.70333 | L15: 10875.737 | M15: 988.70333 | N15: 9887.0333 | O15: 988.70333 | P15: 8898.33 | Q15: 988.70333 | R15: 7909.6267 | S15: 7909.6267
A16: Good Insurance | B16: 1105 | C16: 45658 | D16: Insurance Policy | E16: 1251 | F16: 33724 | G16: 45658 | H16: 45992 | I16: 12 | J16: 2810.3333 | K16: 2810.3333 | L16: 30913.667 | M16: 2810.3333 | N16: 28103.333 | O16: 2810.3333 | P16: 25293 | Q16: 2810.3333 | R16: 22482.667 | S16: 22482.667
A17: Good Insurance | B17: 1106 | C17: 45658 | D17: Insurance Policy | E17: 1251 | F17: 11259 | G17: 45658 | H17: 45992 | I17: 12 | J17: 938.25 | K17: 938.25 | L17: 10320.75 | M17: 938.25 | N17: 9382.5 | O17: 938.25 | P17: 8444.25 | Q17: 938.25 | R17: 7506 | S17: 7506
A18: Good Insurance | B18: 1107 | C18: 45658 | D18: Insurance Policy | E18: 1251 | F18: 23204 | G18: 45658 | H18: 45992 | I18: 12 | J18: 1933.6667 | K18: 1933.6667 | L18: 21270.333 | M18: 1933.6667 | N18: 19336.667 | O18: 1933.6667 | P18: 17403 | Q18: 1933.6667 | R18: 15469.333 | S18: 15469.333
A19: Good Insurance | B19: 1108 | C19: 45658 | D19: Insurance Policy | E19: 1251 | F19: 11861 | G19: 45658 | H19: 45992 | I19: 12 | J19: 988.41667 | K19: 988.41667 | L19: 10872.583 | M19: 988.41667 | N19: 9884.1667 | O19: 988.41667 | P19: 8895.75 | Q19: 988.41667 | R19: 7907.3333 | S19: 7907.3333
A20: Good Insurance | B20: 1109 | C20: 45658 | D20: Insurance Policy | E20: 1251 | F20: 33695 | G20: 45658 | H20: 45992 | I20: 12 | J20: 2807.9167 | K20: 2807.9167 | L20: 30887.083 | M20: 2807.9167 | N20: 28079.167 | O20: 2807.9167 | P20: 25271.25 | Q20: 2807.9167 | R20: 22463.333 | S20: 22463.333
A21: Good Insurance | B21: 1110 | C21: 45658 | D21: Insurance Policy | E21: 1251 | F21: 11259 | G21: 45658 | H21: 45992 | I21: 12 | J21: 938.25 | K21: 938.25 | L21: 10320.75 | M21: 938.25 | N21: 9382.5 | O21: 938.25 | P21: 8444.25 | Q21: 938.25 | R21: 7506 | S21: 7506
A22: Good Insurance | B22: 1111 | C22: 45658 | D22: Insurance Policy | E22: 1251 | F22: 23194 | G22: 45658 | H22: 45992 | I22: 12 | J22: 1932.8333 | K22: 1932.8333 | L22: 21261.167 | M22: 1932.8333 | N22: 19328.333 | O22: 1932.8333 | P22: 17395.5 | Q22: 1932.8333 | R22: 15462.667 | S22: 15462.667
... A31: Good Insurance | B31: 1120 | C31: 45658 | D31: Insurance Policy | E31: 1251 | F31: 33695 | G31: 45658 | H31: 45992 | I31: 12 | J31: 2807.9167 | K31: 2807.9167 | L31: 30887.083 | M31: 2807.9167 | N31: 28079.167 | O31: 2807.9167 | P31: 25271.25 | Q31: 2807.9167 | R31: 22463.333 | S31: 22463.333
A32: Total detail schedule | F32: =SUM(F7:F31) -> 568698.22 | K32: =SUM(K7:K31) -> 45560.428 | L32: =SUM(L7:L31) -> 506657.98 | M32: =SUM(M7:M31) -> 51053.698 | N32: =SUM(N7:N31) -> 461097.55 | O32: =SUM(O7:O31) -> 51053.698 | P32: =SUM(P7:P31) -> 415537.12 | Q32: =SUM(Q7:Q31) -> 51053.698 | R32: =SUM(R7:R31) -> 369976.7 | S32: =SUM(S7:S31) -> 369976.7
A35: Monthly Activity Summary
A36: Month | B36: Beginning Balance | C36: Additions | D36: Amortization | E36: Ending Balance | F36: GL Balance | G36: Difference
A37: Jan-25 | B37: 0 | C37: =SUMPRODUCT((MONTH($C$7:$C$31)=1)*(YEAR($C$7:$C$31)=2025)*($F$7:$F$31)) -> 552218.41 | D37: =SUM(K7:K31) -> 45560.428 | E37: =ROUND(B37+C37-D37,2) -> 506657.98 | F37: 506657.98 | G37: =ROUND(E37-F37,2) -> 0
A38: Feb-25 | B38: =E37 -> 506657.98 | C38: =SUMPRODUCT((MONTH($C$7:$C$31)=2)*(YEAR($C$7:$C$31)=2025)*($F$7:$F$31)) -> 5493.27 | D38: =SUM(M7:M31) -> 51053.698 | E38: =ROUND(B38+C38-D38,2) -> 461097.55 | F38: 461097.55 | G38: =ROUND(E38-F38,2) -> 0
A39: Mar-25 | B39: =E38 -> 461097.55 | C39: =SUMPRODUCT((MONTH($C$7:$C$31)=3)*(YEAR($C$7:$C$31)=2025)*($F$7:$F$31)) -> 5493.27 | D39: =SUM(O7:O31) -> 51053.698 | E39: =ROUND(B39+C39-D39,2) -> 415537.12 | F39: 415537.13 | G39: =ROUND(E39-F39,2) -> -0.01
A40: Apr-25 | B40: =E39 -> 415537.12 | C40: =SUMPRODUCT((MONTH($C$7:$C$31)=4)*(YEAR($C$7:$C$31)=2025)*($F$7:$F$31)) -> 5493.27 | D40: =SUM(Q7:Q31) -> 51053.698 | E40: =ROUND(B40+C40-D40,2) -> 369976.69 | F40: 369976.7 | G40: =ROUND(E40-F40,2) -> -0.01
A41: YTD Total | C41: =SUM(C37:C40) -> 568698.22 | D41: =SUM(D37:D40) -> 198721.52 | E41: =E40 -> 369976.69 | F41: 369976.7 | G41: =ROUND(E41-F41,2) -> -0.01
